[2024-05-11T23:19:03.128+0000] {taskinstance.py:1979} INFO - Dependencies all met for dep_context=non-requeueable deps ti=<TaskInstance: gtaV_reviews_project.load manual__2024-05-11T23:18:55.911081+00:00 [queued]>
[2024-05-11T23:19:03.135+0000] {taskinstance.py:1979} INFO - Dependencies all met for dep_context=requeueable deps ti=<TaskInstance: gtaV_reviews_project.load manual__2024-05-11T23:18:55.911081+00:00 [queued]>
[2024-05-11T23:19:03.136+0000] {taskinstance.py:2193} INFO - Starting attempt 1 of 1
[2024-05-11T23:19:03.150+0000] {taskinstance.py:2217} INFO - Executing <Task(_PythonDecoratedOperator): load> on 2024-05-11 23:18:55.911081+00:00
[2024-05-11T23:19:03.155+0000] {standard_task_runner.py:60} INFO - Started process 600 to run task
[2024-05-11T23:19:03.158+0000] {standard_task_runner.py:87} INFO - Running: ['***', 'tasks', 'run', 'gtaV_reviews_project', 'load', 'manual__2024-05-11T23:18:55.911081+00:00', '--job-id', '17', '--raw', '--subdir', 'DAGS_FOLDER/gtaV_reviews_pipeline.py', '--cfg-path', '/tmp/tmpol2pxz12']
[2024-05-11T23:19:03.159+0000] {standard_task_runner.py:88} INFO - Job 17: Subtask load
[2024-05-11T23:19:03.206+0000] {task_command.py:423} INFO - Running <TaskInstance: gtaV_reviews_project.load manual__2024-05-11T23:18:55.911081+00:00 [running]> on host 93cdc42157bb
[2024-05-11T23:19:03.267+0000] {taskinstance.py:2513} INFO - Exporting env vars: AIRFLOW_CTX_DAG_OWNER='***' AIRFLOW_CTX_DAG_ID='gtaV_reviews_project' AIRFLOW_CTX_TASK_ID='load' AIRFLOW_CTX_EXECUTION_DATE='2024-05-11T23:18:55.911081+00:00' AIRFLOW_CTX_TRY_NUMBER='1' AIRFLOW_CTX_DAG_RUN_ID='manual__2024-05-11T23:18:55.911081+00:00'
[2024-05-11T23:19:03.274+0000] {taskinstance.py:2731} ERROR - Task failed with exception
Traceback (most recent call last):
  File "/home/airflow/.local/lib/python3.8/site-packages/airflow/models/taskinstance.py", line 444, in _execute_task
    result = _execute_callable(context=context, **execute_callable_kwargs)
  File "/home/airflow/.local/lib/python3.8/site-packages/airflow/models/taskinstance.py", line 414, in _execute_callable
    return execute_callable(context=context, **execute_callable_kwargs)
  File "/home/airflow/.local/lib/python3.8/site-packages/airflow/decorators/base.py", line 241, in execute
    return_value = super().execute(context)
  File "/home/airflow/.local/lib/python3.8/site-packages/airflow/operators/python.py", line 200, in execute
    return_value = self.execute_callable()
  File "/home/airflow/.local/lib/python3.8/site-packages/airflow/operators/python.py", line 217, in execute_callable
    return self.python_callable(*self.op_args, **self.op_kwargs)
  File "/opt/airflow/dags/gtaV_reviews_pipeline.py", line 68, in load
    cleaned_data.to_json('/opt/airflow/data/cleaned_GTAV_Reviews.json', orient='records', lines=True)
  File "/home/airflow/.local/lib/python3.8/site-packages/pandas/core/generic.py", line 2532, in to_json
    return json.to_json(
  File "/home/airflow/.local/lib/python3.8/site-packages/pandas/io/json/_json.py", line 198, in to_json
    with get_handle(
  File "/home/airflow/.local/lib/python3.8/site-packages/pandas/io/common.py", line 737, in get_handle
    check_parent_directory(str(handle))
  File "/home/airflow/.local/lib/python3.8/site-packages/pandas/io/common.py", line 600, in check_parent_directory
    raise OSError(rf"Cannot save file into a non-existent directory: '{parent}'")
OSError: Cannot save file into a non-existent directory: '/opt/***/data'
[2024-05-11T23:19:03.286+0000] {taskinstance.py:1149} INFO - Marking task as FAILED. dag_id=gtaV_reviews_project, task_id=load, execution_date=20240511T231855, start_date=20240511T231903, end_date=20240511T231903
[2024-05-11T23:19:03.297+0000] {standard_task_runner.py:107} ERROR - Failed to execute job 17 for task load (Cannot save file into a non-existent directory: '/opt/***/data'; 600)
[2024-05-11T23:19:03.331+0000] {local_task_job_runner.py:234} INFO - Task exited with return code 1
[2024-05-11T23:19:03.343+0000] {taskinstance.py:3312} INFO - 0 downstream tasks scheduled from follow-on schedule check
