[2024-05-14T03:04:26.862+0000] {taskinstance.py:1979} INFO - Dependencies all met for dep_context=non-requeueable deps ti=<TaskInstance: gtaV_reviews_project.calculate manual__2024-05-14T03:04:06.888956+00:00 [queued]>
[2024-05-14T03:04:26.875+0000] {taskinstance.py:1979} INFO - Dependencies all met for dep_context=requeueable deps ti=<TaskInstance: gtaV_reviews_project.calculate manual__2024-05-14T03:04:06.888956+00:00 [queued]>
[2024-05-14T03:04:26.877+0000] {taskinstance.py:2193} INFO - Starting attempt 1 of 1
[2024-05-14T03:04:26.896+0000] {taskinstance.py:2217} INFO - Executing <Task(_PythonDecoratedOperator): calculate> on 2024-05-14 03:04:06.888956+00:00
[2024-05-14T03:04:26.903+0000] {standard_task_runner.py:60} INFO - Started process 1042 to run task
[2024-05-14T03:04:26.907+0000] {standard_task_runner.py:87} INFO - Running: ['***', 'tasks', 'run', 'gtaV_reviews_project', 'calculate', 'manual__2024-05-14T03:04:06.888956+00:00', '--job-id', '60', '--raw', '--subdir', 'DAGS_FOLDER/gtaV_reviews_pipeline.py', '--cfg-path', '/tmp/tmpvz9_uo2t']
[2024-05-14T03:04:26.909+0000] {standard_task_runner.py:88} INFO - Job 60: Subtask calculate
[2024-05-14T03:04:26.962+0000] {task_command.py:423} INFO - Running <TaskInstance: gtaV_reviews_project.calculate manual__2024-05-14T03:04:06.888956+00:00 [running]> on host 9060b0e6df13
[2024-05-14T03:04:27.056+0000] {taskinstance.py:2513} INFO - Exporting env vars: AIRFLOW_CTX_DAG_OWNER='***' AIRFLOW_CTX_DAG_ID='gtaV_reviews_project' AIRFLOW_CTX_TASK_ID='calculate' AIRFLOW_CTX_EXECUTION_DATE='2024-05-14T03:04:06.888956+00:00' AIRFLOW_CTX_TRY_NUMBER='1' AIRFLOW_CTX_DAG_RUN_ID='manual__2024-05-14T03:04:06.888956+00:00'
[2024-05-14T03:04:27.156+0000] {taskinstance.py:2731} ERROR - Task failed with exception
Traceback (most recent call last):
  File "/home/airflow/.local/lib/python3.8/site-packages/airflow/models/taskinstance.py", line 444, in _execute_task
    result = _execute_callable(context=context, **execute_callable_kwargs)
  File "/home/airflow/.local/lib/python3.8/site-packages/airflow/models/taskinstance.py", line 414, in _execute_callable
    return execute_callable(context=context, **execute_callable_kwargs)
  File "/home/airflow/.local/lib/python3.8/site-packages/airflow/decorators/base.py", line 241, in execute
    return_value = super().execute(context)
  File "/home/airflow/.local/lib/python3.8/site-packages/airflow/operators/python.py", line 200, in execute
    return_value = self.execute_callable()
  File "/home/airflow/.local/lib/python3.8/site-packages/airflow/operators/python.py", line 217, in execute_callable
    return self.python_callable(*self.op_args, **self.op_kwargs)
  File "/opt/airflow/dags/gtaV_reviews_pipeline.py", line 109, in calculate
    with open("/opt/airflow/app/calculations.json", "w") as outfile:
FileNotFoundError: [Errno 2] No such file or directory: '/opt/airflow/app/calculations.json'
[2024-05-14T03:04:27.173+0000] {taskinstance.py:1149} INFO - Marking task as FAILED. dag_id=gtaV_reviews_project, task_id=calculate, execution_date=20240514T030406, start_date=20240514T030426, end_date=20240514T030427
[2024-05-14T03:04:27.188+0000] {standard_task_runner.py:107} ERROR - Failed to execute job 60 for task calculate ([Errno 2] No such file or directory: '/opt/airflow/app/calculations.json'; 1042)
[2024-05-14T03:04:27.203+0000] {local_task_job_runner.py:234} INFO - Task exited with return code 1
[2024-05-14T03:04:27.219+0000] {taskinstance.py:3312} INFO - 0 downstream tasks scheduled from follow-on schedule check
