[2024-05-11T23:06:54.814+0000] {taskinstance.py:1979} INFO - Dependencies all met for dep_context=non-requeueable deps ti=<TaskInstance: gtaV_reviews_project.extract manual__2024-05-11T23:06:53.863408+00:00 [queued]>
[2024-05-11T23:06:54.820+0000] {taskinstance.py:1979} INFO - Dependencies all met for dep_context=requeueable deps ti=<TaskInstance: gtaV_reviews_project.extract manual__2024-05-11T23:06:53.863408+00:00 [queued]>
[2024-05-11T23:06:54.821+0000] {taskinstance.py:2193} INFO - Starting attempt 1 of 1
[2024-05-11T23:06:54.833+0000] {taskinstance.py:2217} INFO - Executing <Task(_PythonDecoratedOperator): extract> on 2024-05-11 23:06:53.863408+00:00
[2024-05-11T23:06:54.838+0000] {standard_task_runner.py:60} INFO - Started process 186 to run task
[2024-05-11T23:06:54.840+0000] {standard_task_runner.py:87} INFO - Running: ['***', 'tasks', 'run', 'gtaV_reviews_project', 'extract', 'manual__2024-05-11T23:06:53.863408+00:00', '--job-id', '8', '--raw', '--subdir', 'DAGS_FOLDER/gtaV_reviews_pipeline.py', '--cfg-path', '/tmp/tmp1d0dadz5']
[2024-05-11T23:06:54.841+0000] {standard_task_runner.py:88} INFO - Job 8: Subtask extract
[2024-05-11T23:06:54.885+0000] {task_command.py:423} INFO - Running <TaskInstance: gtaV_reviews_project.extract manual__2024-05-11T23:06:53.863408+00:00 [running]> on host 93cdc42157bb
[2024-05-11T23:06:54.941+0000] {taskinstance.py:2513} INFO - Exporting env vars: AIRFLOW_CTX_DAG_OWNER='***' AIRFLOW_CTX_DAG_ID='gtaV_reviews_project' AIRFLOW_CTX_TASK_ID='extract' AIRFLOW_CTX_EXECUTION_DATE='2024-05-11T23:06:53.863408+00:00' AIRFLOW_CTX_TRY_NUMBER='1' AIRFLOW_CTX_DAG_RUN_ID='manual__2024-05-11T23:06:53.863408+00:00'
[2024-05-11T23:06:59.100+0000] {taskinstance.py:2731} ERROR - Task failed with exception
Traceback (most recent call last):
  File "/home/airflow/.local/lib/python3.8/site-packages/airflow/models/taskinstance.py", line 444, in _execute_task
    result = _execute_callable(context=context, **execute_callable_kwargs)
  File "/home/airflow/.local/lib/python3.8/site-packages/airflow/models/taskinstance.py", line 414, in _execute_callable
    return execute_callable(context=context, **execute_callable_kwargs)
  File "/home/airflow/.local/lib/python3.8/site-packages/airflow/decorators/base.py", line 241, in execute
    return_value = super().execute(context)
  File "/home/airflow/.local/lib/python3.8/site-packages/airflow/operators/python.py", line 200, in execute
    return_value = self.execute_callable()
  File "/home/airflow/.local/lib/python3.8/site-packages/airflow/operators/python.py", line 217, in execute_callable
    return self.python_callable(*self.op_args, **self.op_kwargs)
  File "/opt/airflow/dags/gtaV_reviews_pipeline.py", line 25, in extract
    data = pd.read_excel('testFile.xlsx')
  File "/home/airflow/.local/lib/python3.8/site-packages/pandas/io/excel/_base.py", line 478, in read_excel
    io = ExcelFile(io, storage_options=storage_options, engine=engine)
  File "/home/airflow/.local/lib/python3.8/site-packages/pandas/io/excel/_base.py", line 1496, in __init__
    ext = inspect_excel_format(
  File "/home/airflow/.local/lib/python3.8/site-packages/pandas/io/excel/_base.py", line 1371, in inspect_excel_format
    with get_handle(
  File "/home/airflow/.local/lib/python3.8/site-packages/pandas/io/common.py", line 868, in get_handle
    handle = open(handle, ioargs.mode)
FileNotFoundError: [Errno 2] No such file or directory: 'testFile.xlsx'
[2024-05-11T23:06:59.118+0000] {taskinstance.py:1149} INFO - Marking task as FAILED. dag_id=gtaV_reviews_project, task_id=extract, execution_date=20240511T230653, start_date=20240511T230654, end_date=20240511T230659
[2024-05-11T23:06:59.142+0000] {standard_task_runner.py:107} ERROR - Failed to execute job 8 for task extract ([Errno 2] No such file or directory: 'testFile.xlsx'; 186)
[2024-05-11T23:06:59.156+0000] {local_task_job_runner.py:234} INFO - Task exited with return code 1
[2024-05-11T23:06:59.181+0000] {taskinstance.py:3312} INFO - 0 downstream tasks scheduled from follow-on schedule check
