[2024-05-14T02:35:27.900+0000] {taskinstance.py:1979} INFO - Dependencies all met for dep_context=non-requeueable deps ti=<TaskInstance: gtaV_reviews_project.calculate manual__2024-05-14T02:35:03.646523+00:00 [queued]>
[2024-05-14T02:35:27.910+0000] {taskinstance.py:1979} INFO - Dependencies all met for dep_context=requeueable deps ti=<TaskInstance: gtaV_reviews_project.calculate manual__2024-05-14T02:35:03.646523+00:00 [queued]>
[2024-05-14T02:35:27.917+0000] {taskinstance.py:2193} INFO - Starting attempt 1 of 1
[2024-05-14T02:35:27.934+0000] {taskinstance.py:2217} INFO - Executing <Task(_PythonDecoratedOperator): calculate> on 2024-05-14 02:35:03.646523+00:00
[2024-05-14T02:35:27.941+0000] {standard_task_runner.py:60} INFO - Started process 566 to run task
[2024-05-14T02:35:27.943+0000] {standard_task_runner.py:87} INFO - Running: ['***', 'tasks', 'run', 'gtaV_reviews_project', 'calculate', 'manual__2024-05-14T02:35:03.646523+00:00', '--job-id', '51', '--raw', '--subdir', 'DAGS_FOLDER/gtaV_reviews_pipeline.py', '--cfg-path', '/tmp/tmp_vg18dxf']
[2024-05-14T02:35:27.945+0000] {standard_task_runner.py:88} INFO - Job 51: Subtask calculate
[2024-05-14T02:35:28.041+0000] {task_command.py:423} INFO - Running <TaskInstance: gtaV_reviews_project.calculate manual__2024-05-14T02:35:03.646523+00:00 [running]> on host 9060b0e6df13
[2024-05-14T02:35:28.139+0000] {taskinstance.py:2513} INFO - Exporting env vars: AIRFLOW_CTX_DAG_OWNER='***' AIRFLOW_CTX_DAG_ID='gtaV_reviews_project' AIRFLOW_CTX_TASK_ID='calculate' AIRFLOW_CTX_EXECUTION_DATE='2024-05-14T02:35:03.646523+00:00' AIRFLOW_CTX_TRY_NUMBER='1' AIRFLOW_CTX_DAG_RUN_ID='manual__2024-05-14T02:35:03.646523+00:00'
[2024-05-14T02:35:28.233+0000] {taskinstance.py:2731} ERROR - Task failed with exception
Traceback (most recent call last):
  File "/home/airflow/.local/lib/python3.8/site-packages/airflow/models/taskinstance.py", line 444, in _execute_task
    result = _execute_callable(context=context, **execute_callable_kwargs)
  File "/home/airflow/.local/lib/python3.8/site-packages/airflow/models/taskinstance.py", line 414, in _execute_callable
    return execute_callable(context=context, **execute_callable_kwargs)
  File "/home/airflow/.local/lib/python3.8/site-packages/airflow/decorators/base.py", line 241, in execute
    return_value = super().execute(context)
  File "/home/airflow/.local/lib/python3.8/site-packages/airflow/operators/python.py", line 200, in execute
    return_value = self.execute_callable()
  File "/home/airflow/.local/lib/python3.8/site-packages/airflow/operators/python.py", line 217, in execute_callable
    return self.python_callable(*self.op_args, **self.op_kwargs)
  File "/opt/airflow/dags/gtaV_reviews_pipeline.py", line 109, in calculate
    with open("/app/calculations.json", "w") as outfile:
FileNotFoundError: [Errno 2] No such file or directory: '/app/calculations.json'
[2024-05-14T02:35:28.326+0000] {taskinstance.py:1149} INFO - Marking task as FAILED. dag_id=gtaV_reviews_project, task_id=calculate, execution_date=20240514T023503, start_date=20240514T023527, end_date=20240514T023528
[2024-05-14T02:35:28.350+0000] {standard_task_runner.py:107} ERROR - Failed to execute job 51 for task calculate ([Errno 2] No such file or directory: '/app/calculations.json'; 566)
[2024-05-14T02:35:28.399+0000] {local_task_job_runner.py:234} INFO - Task exited with return code 1
[2024-05-14T02:35:28.422+0000] {taskinstance.py:3312} INFO - 0 downstream tasks scheduled from follow-on schedule check
