[2024-05-15T00:14:37.337+0000] {taskinstance.py:1979} INFO - Dependencies all met for dep_context=non-requeueable deps ti=<TaskInstance: gtaV_reviews_project.calculate manual__2024-05-15T00:14:19.773049+00:00 [queued]>
[2024-05-15T00:14:37.350+0000] {taskinstance.py:1979} INFO - Dependencies all met for dep_context=requeueable deps ti=<TaskInstance: gtaV_reviews_project.calculate manual__2024-05-15T00:14:19.773049+00:00 [queued]>
[2024-05-15T00:14:37.351+0000] {taskinstance.py:2193} INFO - Starting attempt 1 of 1
[2024-05-15T00:14:37.370+0000] {taskinstance.py:2217} INFO - Executing <Task(_PythonDecoratedOperator): calculate> on 2024-05-15 00:14:19.773049+00:00
[2024-05-15T00:14:37.376+0000] {standard_task_runner.py:60} INFO - Started process 361 to run task
[2024-05-15T00:14:37.380+0000] {standard_task_runner.py:87} INFO - Running: ['***', 'tasks', 'run', 'gtaV_reviews_project', 'calculate', 'manual__2024-05-15T00:14:19.773049+00:00', '--job-id', '97', '--raw', '--subdir', 'DAGS_FOLDER/gtaV_reviews_pipeline.py', '--cfg-path', '/tmp/tmpr_pj2los']
[2024-05-15T00:14:37.382+0000] {standard_task_runner.py:88} INFO - Job 97: Subtask calculate
[2024-05-15T00:14:37.435+0000] {task_command.py:423} INFO - Running <TaskInstance: gtaV_reviews_project.calculate manual__2024-05-15T00:14:19.773049+00:00 [running]> on host bc094ad74ee5
[2024-05-15T00:14:37.519+0000] {taskinstance.py:2513} INFO - Exporting env vars: AIRFLOW_CTX_DAG_OWNER='***' AIRFLOW_CTX_DAG_ID='gtaV_reviews_project' AIRFLOW_CTX_TASK_ID='calculate' AIRFLOW_CTX_EXECUTION_DATE='2024-05-15T00:14:19.773049+00:00' AIRFLOW_CTX_TRY_NUMBER='1' AIRFLOW_CTX_DAG_RUN_ID='manual__2024-05-15T00:14:19.773049+00:00'
[2024-05-15T00:14:37.606+0000] {taskinstance.py:2731} ERROR - Task failed with exception
Traceback (most recent call last):
  File "/home/airflow/.local/lib/python3.8/site-packages/airflow/models/taskinstance.py", line 444, in _execute_task
    result = _execute_callable(context=context, **execute_callable_kwargs)
  File "/home/airflow/.local/lib/python3.8/site-packages/airflow/models/taskinstance.py", line 414, in _execute_callable
    return execute_callable(context=context, **execute_callable_kwargs)
  File "/home/airflow/.local/lib/python3.8/site-packages/airflow/decorators/base.py", line 241, in execute
    return_value = super().execute(context)
  File "/home/airflow/.local/lib/python3.8/site-packages/airflow/operators/python.py", line 200, in execute
    return_value = self.execute_callable()
  File "/home/airflow/.local/lib/python3.8/site-packages/airflow/operators/python.py", line 217, in execute_callable
    return self.python_callable(*self.op_args, **self.op_kwargs)
  File "/opt/airflow/dags/gtaV_reviews_pipeline.py", line 109, in calculate
    totalHours += playerHours.index(index)
ValueError: 1 is not in list
[2024-05-15T00:14:37.627+0000] {taskinstance.py:1149} INFO - Marking task as FAILED. dag_id=gtaV_reviews_project, task_id=calculate, execution_date=20240515T001419, start_date=20240515T001437, end_date=20240515T001437
[2024-05-15T00:14:37.641+0000] {standard_task_runner.py:107} ERROR - Failed to execute job 97 for task calculate (1 is not in list; 361)
[2024-05-15T00:14:37.674+0000] {local_task_job_runner.py:234} INFO - Task exited with return code 1
[2024-05-15T00:14:37.690+0000] {taskinstance.py:3312} INFO - 0 downstream tasks scheduled from follow-on schedule check
