[2024-05-14T03:08:59.683+0000] {taskinstance.py:1979} INFO - Dependencies all met for dep_context=non-requeueable deps ti=<TaskInstance: gtaV_reviews_project.calculate manual__2024-05-14T03:08:40.693605+00:00 [queued]>
[2024-05-14T03:08:59.702+0000] {taskinstance.py:1979} INFO - Dependencies all met for dep_context=requeueable deps ti=<TaskInstance: gtaV_reviews_project.calculate manual__2024-05-14T03:08:40.693605+00:00 [queued]>
[2024-05-14T03:08:59.703+0000] {taskinstance.py:2193} INFO - Starting attempt 1 of 1
[2024-05-14T03:08:59.719+0000] {taskinstance.py:2217} INFO - Executing <Task(_PythonDecoratedOperator): calculate> on 2024-05-14 03:08:40.693605+00:00
[2024-05-14T03:08:59.726+0000] {standard_task_runner.py:60} INFO - Started process 1142 to run task
[2024-05-14T03:08:59.730+0000] {standard_task_runner.py:87} INFO - Running: ['***', 'tasks', 'run', 'gtaV_reviews_project', 'calculate', 'manual__2024-05-14T03:08:40.693605+00:00', '--job-id', '63', '--raw', '--subdir', 'DAGS_FOLDER/gtaV_reviews_pipeline.py', '--cfg-path', '/tmp/tmp7rc8h_jw']
[2024-05-14T03:08:59.731+0000] {standard_task_runner.py:88} INFO - Job 63: Subtask calculate
[2024-05-14T03:08:59.796+0000] {task_command.py:423} INFO - Running <TaskInstance: gtaV_reviews_project.calculate manual__2024-05-14T03:08:40.693605+00:00 [running]> on host 9060b0e6df13
[2024-05-14T03:08:59.932+0000] {taskinstance.py:2513} INFO - Exporting env vars: AIRFLOW_CTX_DAG_OWNER='***' AIRFLOW_CTX_DAG_ID='gtaV_reviews_project' AIRFLOW_CTX_TASK_ID='calculate' AIRFLOW_CTX_EXECUTION_DATE='2024-05-14T03:08:40.693605+00:00' AIRFLOW_CTX_TRY_NUMBER='1' AIRFLOW_CTX_DAG_RUN_ID='manual__2024-05-14T03:08:40.693605+00:00'
[2024-05-14T03:09:00.077+0000] {taskinstance.py:2731} ERROR - Task failed with exception
Traceback (most recent call last):
  File "/home/airflow/.local/lib/python3.8/site-packages/airflow/models/taskinstance.py", line 444, in _execute_task
    result = _execute_callable(context=context, **execute_callable_kwargs)
  File "/home/airflow/.local/lib/python3.8/site-packages/airflow/models/taskinstance.py", line 414, in _execute_callable
    return execute_callable(context=context, **execute_callable_kwargs)
  File "/home/airflow/.local/lib/python3.8/site-packages/airflow/decorators/base.py", line 241, in execute
    return_value = super().execute(context)
  File "/home/airflow/.local/lib/python3.8/site-packages/airflow/operators/python.py", line 200, in execute
    return_value = self.execute_callable()
  File "/home/airflow/.local/lib/python3.8/site-packages/airflow/operators/python.py", line 217, in execute_callable
    return self.python_callable(*self.op_args, **self.op_kwargs)
  File "/opt/airflow/dags/gtaV_reviews_pipeline.py", line 109, in calculate
    with open("/app/calculations.json", "w") as outfile:
FileNotFoundError: [Errno 2] No such file or directory: '/app/calculations.json'
[2024-05-14T03:09:00.106+0000] {taskinstance.py:1149} INFO - Marking task as FAILED. dag_id=gtaV_reviews_project, task_id=calculate, execution_date=20240514T030840, start_date=20240514T030859, end_date=20240514T030900
[2024-05-14T03:09:00.126+0000] {standard_task_runner.py:107} ERROR - Failed to execute job 63 for task calculate ([Errno 2] No such file or directory: '/app/calculations.json'; 1142)
[2024-05-14T03:09:00.145+0000] {local_task_job_runner.py:234} INFO - Task exited with return code 1
[2024-05-14T03:09:00.171+0000] {taskinstance.py:3312} INFO - 0 downstream tasks scheduled from follow-on schedule check
